Workbook

Sheet 작성요령
B1: Project 체크리스트 작성요령 (설계성과품 기술검토)
B3: 1. 시트 구성
B4: 시트 | C4: 용도 | D4: 입력 위치 | E4: 비고
B5: 작성요령 | C5: 이 시트. 사용 순서 · 색상 · 판정 기준 · 작성 예시 | D5: -
B6: 검토서 | C6: 설계성과품 기술검토 한 장: 설계 사양 입력 + 점검 + 판정 + 검토의견 + 요청사항 (1~7번 섹션) | D6: D열(도서·도면 값), F열(판정), G열(검토의견) | E6: 계약 · 견적 · 금액 항목은 포함하지 않음 (기술검토 전용)
B7: 기술제안서 / 설계 / 시공 / 시운전 | C7: 단계별 재검토 Check List. 상세 기술검토는 [검토서]에서 한 번만 하고, 단계 시트는 단계 고유 항목과 이전 단계 결과 재확인만 담음. 설계 시트의 "실시설계" 열은 [검토서] 입력값으로 자동 채워짐 | D7: 설계: 기술제안 내용 · 비고 | E7: 시공 상단: 검토서 미해소 · 설계변경 건수 자동 / 시운전 상단: 시공 미완료(×) 건수 자동
B9: 2. 사용 순서
B10: 단계 | C10: 할 일 | D10: 확인할 것
B11: ① 상단 정보 | C11: 현장명 · 설계사 · 검토일/검토자 · 처리공정 입력. 1번 섹션 '공급펌프 유입시간 기준' 칸(기본 90분) 확인 | D11: 현장명을 넣으면 제목에 자동 표시
B12: ② 1~5번 섹션 | C12: D열에 도서·도면 값을 입력 (숫자는 단위 열과 맞춰서). 계산이 필요한 값(Q/Cycle, 유효용량, HRT, 유입시간, 배출량 등)은 자동 | D12: 초록색 칸은 입력하지 않음
B13: ③ 판정 · 검토의견 | C13: 점검 행마다 F열에서 확인/검토/부적합 선택 후 G열에 의견 기재. 자동 판정 행은 F·G가 채워짐 | D13: 판정이 비어 있으면 "미작성"으로 집계
B14: ④ 7번 요청사항 | C14: "검토 · 부적합" 항목이 자동 나열됨. 오른쪽 "요청 사항"만 직접 작성 | D14: 8건 초과 시 마지막 줄에 나머지 건수 표시
B15: ⑤ 설계 Check List | C15: 기술제안 내용을 입력하면 실시설계 열은 자동 비교 (동력 · 반응조 규격 변경 필요 여부 등) | D15: "필요"면 비고에 사유 기재
B16: ⑥ 마무리 | C16: 상단 "점검 현황"에서 미작성 0건 확인 → 하단 검토/확인란 서명
B18: 3. 색상 규칙
B19: 색 | C19: 의미 | D19: 작성 방법
B20: 노란색 (파란 글씨) | C20: 직접 입력하는 칸 | D20: 값 · 의견 입력 또는 목록 선택
B21: 초록색 | C21: 자동 계산 · 자동 판정 칸 | D21: 입력 불필요. 덮어써도 되지만 그 칸은 자동 연결이 끊김
B22: 회색 | C22: 제목 · 항목 이름 · 해당 없음 | D22: 수정하지 않음
B23: 빨강 / 파랑 표시 | C23: 판정이 부적합(빨강) · 검토(파랑)이면 자동 강조 | D23: 별도 작업 없음
B25: 4. 판정 기준
B26: 판정 | C26: 뜻 | D26: 예
B27: 확인 | C27: 도서·도면이 기준에 맞고 조치 불필요 | D27: 기어드모터 30kW, 시방서와 도면 일치
B28: 검토 | C28: 확인이 더 필요하거나 설계사에 확인·자료 요청 필요 (부적합은 아님) | D28: 슬리브 도면 없음 → 도면 요청 / 이더넷으로 통신방식 변경 요청
B29: 부적합 | C29: 기준 · 시방서와 맞지 않아 수정 요청 필요 | D29: 시방서 30kW, 도면 11kW / 유입시간 124분 > 기준 90분
B31: 5. 자동 계산 · 자동 판정 규칙
B32: 항목 | C32: 규칙 | D32: 결과 표시
B33: Q/Cycle | C33: 설계유량 ÷ SET ÷ 일 사이클 수 (기본 4) | D33: ㎥/cycle
B34: 유량조정조 · 처리수조 | C34: 유효용량 = 가로 × 세로 × 수심 × 지수, 체류시간 = 용량 ÷ (설계유량 ÷ 24) | D34: ㎥ · hr (판정은 직접 선택)
B35: 공급펌프 유입시간 | C35: 유입시간(분) = Q/Cycle ÷ 펌프 용량(㎥/min). 기준(기본 90분) 이내면 확인, 초과하면 부적합 | D35: 초과 시 빨간 글씨
B36: 반응조 유효용량 · HRT | C36: 유효용량 = 가로 × 세로 × HWL, HRT = 유효용량 × SET ÷ (설계유량 ÷ 24) | D36: 목표 HRT 대비 % 표시
B37: 도면 · 시방서 동력 | C37: 시방서 kW와 도면 kW가 같으면 확인, 다르면 부적합 | D37: 일치/불일치
B38: 배출량 · 배출소요시간 | C38: 배출량 = 가로 × 세로 × (HWL − LWL) ≥ Q/Cycle. 배출소요시간 = 배출 대상 유량/Cycle ÷ 배출유량 — 배출 대상 유량은 잉여슬러지 인발로 수위가 낮아진 뒤의 배출장치 설계유입량(비우면 Q/Cycle). 판정은 계산서와 같이 필요 배출유량을 ROUND(…,3)한 값이 배출유량(QIN) 이하면 확인 | D38: 아니면 부적합
B39: 1차 전원 | C39: 전원 용량 ≥ (기어드모터 + 전동윈치) × SET 이면 확인, 아니면 부적합 | D39: 충족/부족
B40: 2차 배선 거리 | C40: 구간 합계 × 여유율(기본 1.3) | D40: 구간은 =20+8+20 처럼 입력 가능
B41: 총인 공급펌프 | C41: 유입시간 = Q/Cycle ÷ 펌프 용량. 지침 기준이 없어 시간만 표시 | D41: 판정은 직접 선택
B43: 6. 입력 → 자동 반영 지도
B44: 입력한 곳 | C44: 자동 반영되는 곳 | D44: 내용
B45: 검토서 D열 (사양 값) | C45: 같은 시트의 자동 계산 · 판정 · 상단 점검 현황 | D45: Q/Cycle, 유효용량, HRT, 유입시간, 배출량, 동력부하 등
B46: 검토서 D열 (사양 값) | C46: 설계 Check List 실시설계 열 | D46: 포기장치 · 배출장치 · 반응조 규격 · 총인 · 제어반 항목
...

Sheet 검토서
A1: =IF($C$3="","설계성과품 검토서",$C$3&" 설계성과품 검토서") -> 설계성과품 검토서
A2: ※ 노란색 = 직접 입력 / 초록색 = 자동 계산·자동 판정(필요하면 덮어써서 수정 가능). 도서·도면 값을 D열에 입력하면 판정·검토의견·설계 Check List에 자동 반영됩니다. (작성 방법: [작성요령] 시트)
A3: 현장명
A4: 설계사
A5: 검토일 · 검토자
A6: 처리공정
A7: 점검 현황 | C7: ="전체 "&SUM($K$1:$K$105)&"건 · 확인 "&COUNTIF($F$1:$F$105,"확인")&" · 검토 "&COUNTIF($F$1:$F$105,"검토")&" · 부적합 "&COUNTIF($F$1:$F$105,"부적합")&" · 미작성 "&(SUM($K$1:$K$105)-COUNTIF($F$1:$F$105,"확인")-COUNTIF($F$1:$F$105,"검토")-COUNTIF($F$1:$F$105,"부적합")) -> 전체 37건 · 확인 0 · 검토 0 · 부적합 0 · 미작성 37
I8: 순번 | J8: 의견 요약(자동) | K8: 집계
A9: 1. 설계 기본 사양 (용량계산서 기준)
A10: No | B10: 구분 | C10: 점검항목 | D10: 도서 · 도면 | E10: 단위 | F10: 판정 | G10: 검토의견 | H10: 비고
A11: =IF(C11="","",COUNTA(C$11:C11)) -> 1 | B11: 공통 | C11: 시설용량 | E11: ㎥/d
A12: =IF(C12="","",COUNTA(C$11:C12)) -> 2 | B12: 공통 | C12: 설계유량 | E12: ㎥/d
A13: =IF(C13="","",COUNTA(C$11:C13)) -> 3 | B13: 공통 | C13: 반응조 수 (SET) | E13: 지
A14: =IF(C14="","",COUNTA(C$11:C14)) -> 4 | B14: 공통 | C14: 일 사이클 수 (지당) | D14: 4 | E14: 회/d
A15: =IF(C15="","",COUNTA(C$11:C15)) -> 5 | B15: 공통 | C15: Q/Cycle (지당) = 설계유량 ÷ SET ÷ 사이클 수 | D15: =IF(OR($D$12="",$D$13="",$D$14=""),"",$D$12/$D$13/$D$14) | E15: ㎥/cycle
A16: =IF(C16="","",COUNTA(C$11:C16)) -> 6 | B16: 공통 | C16: 목표 HRT (용량계산서) | E16: hr
A17: =IF(C17="","",COUNTA(C$11:C17)) -> 7 | B17: 공통 | C17: SRT | E17: 일
A18: =IF(C18="","",COUNTA(C$11:C18)) -> 8 | B18: 공통 | C18: 공급펌프 유입시간 기준 (지침) | D18: 90 | E18: 분
A20: 2. 유량 조정조 설비 (토목 · 기계)
A21: No | B21: 구분 | C21: 점검항목 | D21: 도서 · 도면 | E21: 단위 | F21: 판정 | G21: 검토의견 | H21: 비고
A22: =IF(C22="","",COUNTA(C$22:C22)) -> 1 | B22: 토목 | C22: 유량조정조 가로 | E22: m
A23: =IF(C23="","",COUNTA(C$22:C23)) -> 2 | B23: 토목 | C23: 유량조정조 세로 | E23: m
A24: =IF(C24="","",COUNTA(C$22:C24)) -> 3 | B24: 토목 | C24: 유량조정조 수심 | E24: m
A25: =IF(C25="","",COUNTA(C$22:C25)) -> 4 | B25: 토목 | C25: 유량조정조 지수 | D25: 1 | E25: 지
A26: =IF(C26="","",COUNTA(C$22:C26)) -> 5 | B26: 토목 | C26: 유량조정조 유효용량 (가로 × 세로 × 수심 × 지수) | D26: =IF(COUNT($D$22,$D$23,$D$24,$D$25)<4,"",$D$22*$D$23*$D$24*$D$25) | E26: ㎥
A27: =IF(C27="","",COUNTA(C$22:C27)) -> 6 | B27: 토목 | C27: 유량조정조 체류시간 적정성 검토 (용량 ÷ 시간유량) | D27: =IF(OR($D$26="",$D$12=""),"",$D$26/($D$12/24)) | E27: hr | I27: =IF(OR(F27="부적합",F27="검토"),MAX(I$1:I26)+1,"") | J27: =LEFT(C27,FIND("|",SUBSTITUTE(C27," (","|")&"|")-1)&IF(OR(D27="",G27=""),IF(D27<>"",": "&IF(D27="","",D27&IF(ISNUMBER(D27),IF(E27="",""," "&E27),"")),IF(G27<>"",": "&G27,"")),": "&IF(D27="","",D27&IF(ISNUMBER(D27),IF(E27="",""," "&E27),""))&" / "&G27) -> 유량조정조 체류시간 적정성 검토 | K27: =IF(C27<>"",1,0) -> 1
A28: =IF(C28="","",COUNTA(C$22:C28)) -> 7 | B28: 토목 | C28: 유량조정조 운전 수위 및 유효수심 검토 | I28: =IF(OR(F28="부적합",F28="검토"),MAX(I$1:I27)+1,"") | J28: =LEFT(C28,FIND("|",SUBSTITUTE(C28," (","|")&"|")-1)&IF(OR(D28="",G28=""),IF(D28<>"",": "&IF(D28="","",D28&IF(ISNUMBER(D28),IF(E28="",""," "&E28),"")),IF(G28<>"",": "&G28,"")),": "&IF(D28="","",D28&IF(ISNUMBER(D28),IF(E28="",""," "&E28),""))&" / "&G28) -> 유량조정조 운전 수위 및 유효수심 검토 | K28: =IF(C28<>"",1,0) -> 1
A29: =IF(C29="","",COUNTA(C$22:C29)) -> 8 | B29: 기계 | C29: 공급펌프 구경 | E29: A
A30: =IF(C30="","",COUNTA(C$22:C30)) -> 9 | B30: 기계 | C30: 공급펌프 용량 | E30: ㎥/min
A31: =IF(C31="","",COUNTA(C$22:C31)) -> 10 | B31: 기계 | C31: 공급펌프 동력 | E31: kW
A32: =IF(C32="","",COUNTA(C$22:C32)) -> 11 | B32: 기계 | C32: 공급펌프 사이클당 유입시간 검토 (Q/Cycle ÷ 펌프 용량) | D32: =IF(OR($D$30="",$D$30=0,$D$15=""),"",$D$15/$D$30) | E32: 분 | F32: =IF(D32="","",IF(D32<=$D$18,"확인","부적합")) | G32: =IF(D32="","","기준 "&$D$18&"분 "&IF(D32<=$D$18,"이내","초과")) | I32: =IF(OR(F32="부적합",F32="검토"),MAX(I$1:I31)+1,"") | J32: =LEFT(C32,FIND("|",SUBSTITUTE(C32," (","|")&"|")-1)&IF(OR(D32="",G32=""),IF(D32<>"",": "&IF(D32="","",D32&IF(ISNUMBER(D32),IF(E32="",""," "&E32),"")),IF(G32<>"",": "&G32,"")),": "&IF(D32="","",D32&IF(ISNUMBER(D32),IF(E32="",""," "&E32),""))&" / "&G32) -> 공급펌프 사이클당 유입시간 검토 | K32: =IF(C32<>"",1,0) -> 1
A33: =IF(C33="","",COUNTA(C$22:C33)) -> 12 | B33: 기계 | C33: 유입 배관 규격 및 밸브 검토 | I33: =IF(OR(F33="부적합",F33="검토"),MAX(I$1:I32)+1,"") | J33: =LEFT(C33,FIND("|",SUBSTITUTE(C33," (","|")&"|")-1)&IF(OR(D33="",G33=""),IF(D33<>"",": "&IF(D33="","",D33&IF(ISNUMBER(D33),IF(E33="",""," "&E33),"")),IF(G33<>"",": "&G33,"")),": "&IF(D33="","",D33&IF(ISNUMBER(D33),IF(E33="",""," "&E33),""))&" / "&G33) -> 유입 배관 규격 및 밸브 검토 | K33: =IF(C33<>"",1,0) -> 1
A35: 3. 생물 반응조 설비 (토목 · 기계)
A36: No | B36: 구분 | C36: 점검항목 | D36: 도서 · 도면 | E36: 단위 | F36: 판정 | G36: 검토의견 | H36: 비고
A37: =IF(C37="","",COUNTA(C$37:C37)) -> 1 | B37: 토목 | C37: 반응조 가로 | E37: m
A38: =IF(C38="","",COUNTA(C$37:C38)) -> 2 | B38: 토목 | C38: 반응조 세로 | E38: m
A39: =IF(C39="","",COUNTA(C$37:C39)) -> 3 | B39: 토목 | C39: 운전수위 LWL | E39: m
A40: =IF(C40="","",COUNTA(C$37:C40)) -> 4 | B40: 토목 | C40: 운전수위 HWL (수심) | E40: m
A41: =IF(C41="","",COUNTA(C$37:C41)) -> 5 | B41: 토목 | C41: 여유고 (HWL ~ 벽체 상단) | E41: m | I41: =IF(OR(F41="부적합",F41="검토"),MAX(I$1:I40)+1,"") | J41: =LEFT(C41,FIND("|",SUBSTITUTE(C41," (","|")&"|")-1)&IF(OR(D41="",G41=""),IF(D41<>"",": "&IF(D41="","",D41&IF(ISNUMBER(D41),IF(E41="",""," "&E41),"")),IF(G41<>"",": "&G41,"")),": "&IF(D41="","",D41&IF(ISNUMBER(D41),IF(E41="",""," "&E41),""))&" / "&G41) -> 여유고 | K41: =IF(C41<>"",1,0) -> 1
A42: =IF(C42="","",COUNTA(C$37:C42)) -> 6 | B42: 토목 | C42: 생물반응조 유효용량 및 운전수위 검토 (가로 × 세로 × HWL) | D42: =IF(OR($D$37="",$D$38="",$D$40=""),"",$D$37*$D$38*$D$40) | E42: ㎥ | G42: =IF(OR($D$39="",$D$40=""),"","배출수위(He) "&TEXT($D$40-$D$39,"0.00")&"m") | I42: =IF(OR(F42="부적합",F42="검토"),MAX(I$1:I41)+1,"") | J42: =LEFT(C42,FIND("|",SUBSTITUTE(C42," (","|")&"|")-1)&IF(OR(D42="",G42=""),IF(D42<>"",": "&IF(D42="","",D42&IF(ISNUMBER(D42),IF(E42="",""," "&E42),"")),IF(G42<>"",": "&G42,"")),": "&IF(D42="","",D42&IF(ISNUMBER(D42),IF(E42="",""," "&E42),""))&" / "&G42) -> 생물반응조 유효용량 및 운전수위 검토 | K42: =IF(C42<>"",1,0) -> 1
...

Sheet 기술제안서
A1: 기술제안서 Check List
A3: 프로젝트 명 :
A4: 구 분 | C4: Check 내용 | D4: 검토자 | E4: 1차검토 | F4: 2차검토 | G4: 비고
A5: 제안서 기획 (PM,부서장,팀장) | C5: 제안서의 작성전반에 대한 PM의 컨셉확인했나?(PM)
C6: 공정계획이 사업목표와 부합되는가?(PM)
C7: 구조물의 배치는 경제성과 유지관리를 고려했나?
C8: 처리공정의 구성과 유지관리의 상관관계검토?
C9: 유지관리비(에너지)소요 자재에 대한 운영계획은 적정한가?
C10: 금번 제안서 작성의 주안점을 설정하였나?
C11: 경쟁사와 평가점수에 대한 보증수질,경제성에 대한 시뮬레이션? | D11: 해당사항없음 | E11: 해당사항없음 | F11: 해당사항없음
A12: 원 본 | B12: 제안서 | C12: 작성지침의 번호순서대로 서술되었는가?
C13: 제안수질이 목표수질 이내인가?
C14: 목표수질 표기가 틀린곳이 없는가?
C15: 쪽수가 제안쪽수 이내인가?
C16: 투시도조감도는 사용하지 않았는가?
C17: 공사비, 유지관리비가 부록과 일치하는가?
C18: 제출문 직인란은 직인이 누락되지 않았는가?
B19: 정상가동 실적증명서 | C19: 기한내 것인가?
C20: 당사특허 적용현장인가?
C21: 특허내용이 포함되었는가?
C22: 적용용량에 맞는가?
C23: 만점 개소수 여유율 50% 이상 첨부했는가?
B24: 도면 | C24: 구조물용량은 지침에 부합하는가?
C25: 계열화는 지침에 부합하는가?
C26: 유입 BOP를 기준으로 설계하였는가?
C27: 십자구조물은 표현되어 있는가?
C28: 체류시간 — 반응조 공급펌프 유입시간이 90분 이내로 설계되었는가?
B29: 기타첨부 서류 | C29: 첨부서류중 빠진것은 없는가? (공동협약서,확약서,성능보증서,자재성능보증서, 기술이전계획서,유지관리보증서,기자재견적서)
C30: 확약서 등 첨부서류 내용 누락사항은 없는가?
C31: 성능보증 수질은 기준 이내인가?
C32: 첨부서류에 누락된 직인란은 없는가?
A33: 사 본 | B33: 제안서 | C33: 표지 및 제출문에 회사명이 언급되지 않았는지?
C34: 공법명, 회사명이 언급된 곳은 없는가?
C35: 부록내역서에 회사명이 언급된 곳은 없는가?
C36: 부록용량계산서에 공법명이 언급된 곳은 없는가?

Sheet 설계
A1: 설계 Check List
A3: 프로젝트 명 :
A4: 구 분 | C4: Check 내용 | D4: 기술제안 내용 | E4: 실시설계 | F4: 비 고
A5: 공법기자재 | C5: 포기장치 형식 | D5: 900형
C6: 포기장치 수량 | D6: 2SET | E6: =IF(검토서!$D$13="","",TEXT(검토서!$D$13,"0")&"SET")
C7: 포기장치 동력 | D7: 4kW | E7: =IF(검토서!$D$51="","",TEXT(검토서!$D$51,"0.#")&"kW")
C8: 포기장치 인버터 사양 | D8: 5.5kW
C9: 배출장치 규격 | D9: 150A | E9: =IF(검토서!$D$59="","",TEXT(검토서!$D$59,"0")&"A")
C10: 배출장치 수량 | D10: 2SET | E10: =IF(검토서!$D$13="","",TEXT(검토서!$D$13,"0")&"SET")
C11: 배출장치 동력 | D11: 0.4kW | E11: =IF(검토서!$D$60="","",TEXT(검토서!$D$60,"0.0#")&"kW")
C12: 포기장치 동하중, 정하중 | D12: 2ton / 1ton
C13: 배출장치 동하중, 정하중 | D13: 0.5ton / 0.3ton
C14: 동력 변경 필요 여부 | D14: 불필요 | E14: =IF(OR(AND(D7="",D11=""),AND(E7="",E11="")),"",IF(AND(D7=E7,D11=E11),"불필요","필요")) | F14: 웹앱 기준 · 초과 시 4개 팀 협의
A15: 공통 | B15: 토목 | C15: 반응조 폭, 길이 | E15: =IF(OR(검토서!$D$37="",검토서!$D$38=""),"",TEXT(검토서!$D$37,"0.0#")&" × "&TEXT(검토서!$D$38,"0.0#")&" m")
C16: 반응조 수위 | E16: =IF(OR(검토서!$D$39="",검토서!$D$40=""),"",TEXT(검토서!$D$39,"0.0#")&" ~ "&TEXT(검토서!$D$40,"0.0#")&" m")
C17: 반응조 규격 변경 필요 여부 | E17: =IF(OR(AND(D15="",D16=""),AND(E15="",E16="")),"",IF(AND(D15=E15,D16=E16),"불필요","필요"))
C18: 잉여슬러지 펌프 피트 반영 여부
C19: 처리수조 펌프 피트 반영 여부 | E19: =IF(검토서!$D$84&검토서!$G$84="","",TRIM(검토서!$D$84&IF(AND(검토서!$D$84<>"",검토서!$G$84<>"")," / ","")&검토서!$G$84))
C20: 맨홀 위치 변경 필요 여부
C21: 단차구조물 변경 필요 여부
B22: 기계 | C22: 유지관리호이스트 레일 / 기자재 규격 | D22: 레일 2ton, 기자재 1ton | E22: =IF(검토서!$D$56&검토서!$G$56="","",TRIM(검토서!$D$56&IF(AND(검토서!$D$56<>"",검토서!$G$56<>"")," / ","")&검토서!$G$56))
C23: 전처리설비 변경 여부
C24: 총인처리설비 배관 포함 여부 (공법사 미포함시 배관공사비 산정 여부 확인) | D24: 총인처리설비 없음 | E24: =IF(검토서!$D$92="","",검토서!$D$92&"")
C25: 계열화 삭제 여부
B26: 전기 | C26: 공법제어반 포함내용 | D26: PLC 이중화 | E26: =IF(검토서!$D$69="","",검토서!$D$69&"")
C27: 감시제어반 RCS 포함여부 | D27: 미포함 | E27: =IF(검토서!$D$70="","",검토서!$D$70&"")
C28: MCC반 포함여부 | D28: 미포함 | E28: =IF(검토서!$D$71="","",검토서!$D$71&"")
C29: 2차배관배선 | D29: 미포함, 실시설계시 반영필요
C30: 공법제어반 전기실 배치 요청 | E30: =IF(검토서!$D$68&검토서!$G$68="","",TRIM(검토서!$D$68&IF(AND(검토서!$D$68<>"",검토서!$G$68<>"")," / ","")&검토서!$G$68))
A31: 기타 | C31: 유입분배조, 탈취기실 배치 위치 확인
A34: 종합 의견 | C34: =IF(검토서!$C$7="","",검토서!$C$7) -> 전체 37건 · 확인 0 · 검토 0 · 부적합 0 · 미작성 37

Sheet 시공
A1: 시공 Check List
A3: 프로젝트 명 :
A4: 구 분 | C4: Check 내용 | D4: 확 인 | E4: 비 고
A5: 설계 재검토 | B5: 검토서 연계 | C5: 설계성과품 검토서의 '검토 · 부적합' 항목이 설계사 회신·도면 수정으로 모두 해소됐는지? | E5: =IFERROR("미해소 "&(COUNTIF(검토서!$F$1:$F$105,"부적합")+COUNTIF(검토서!$F$1:$F$105,"검토"))&"건","") -> 미해소 0건
C6: 설계 Check List의 변경 '필요' 항목이 제작·설치 계획에 반영됐는지? | E6: =IFERROR("변경 필요 "&COUNTIF(설계!$E$5:$E$31,"필요")&"건","") -> 변경 필요 0건
A7: 제작 승인 도서 | B7: 승인도서 | C7: 최종 설계시방서 및 내역 기준으로 작성됐는지?
C8: 제출 시기·부수와 감리단 별도 양식 여부를 확인했는지?
C9: 협력업체에서 받은 보고서의 내용에 오류는 없는지?
C10: 설계시방서와 제작시방서의 차이가 있다면 DEVIATION SHEET를 작성했는지?
B11: 제작 도면 | C11: 최종 설계도면 기준으로 작성됐는지?
C12: 레벨·치수(벽체-슬라브 이격, 배출장치 BOP, 십자구조물 높이, HWL·LWL 대비 터빈 위치)가 현장에 맞게 명시됐는지?
C13: 모터감속기·윈치, GUIDE RAIL·FLOAT ARM 파이프 규격이 실제 사양대로 명시됐는지?
C14: 터빈 프로펠러와 디켄터 공기차단막 상세가 표현됐는지?
C15: 도각 우측 상단 DESCRIPTION 테이블이 현장에 맞게 기입됐는지?
B16: 첨부 서류 | C16: 첨부서류가 보고서 목차와 현장 규격·내용에 맞게 들어갔는지?
C17: 현장에 맞는 규격에 손도장이 바르게 들어갔는지?
B18: 보완작업 | C18: 감리단 보완 지시 사항이 현장 여건과 맞는지?
A19: 공장검사 보고서 | B19: 보고서 | C19: 허용공차 TABLE의 치수가 치수검사체크리스트의 치수와 일치하는지?
B20: 첨부서류 | C20: 기자재 성적서·밀시트와 사진대지가 알맞게 정리됐는지?
B21: 기타사항 | C21: 총인설비기자재는 업체에서 별도로 작성할 것인지?
A22: 설치 안전 | B22: 안전관리 | C22: TBM(작업 전 안전회의)과 위험성평가를 실시하고 기록을 유지하는지?
B23: 특수작업 | C23: 밀폐공간 가스측정·환기, 고소작업 추락방지 조치가 계획서대로 이행되는지?
A24: 준공 도서 | B24: 보고서 ·도면 | C24: 준공 보고서와 준공도면이 실제 현장과 동일하게 작성됐는지?
B25: 첨부서류 | C25: 설치 완료 사진을 요청하여 제대로 받았는지?
B26: 정산 | C26: 실행품의 변동점과 정산 결과를 대조했는지? (CS 인계는 시운전 Check List에서)

Sheet 시운전
A1: 시운전 Check List
A3: 프로젝트 명 :
A4: 구 분 | C4: Check 내용 | D4: 확 인 | E4: 비 고
A5: 시운전 계획 | B5: 선행 확인 | C5: 시공 Check List에 미완료(×) 항목이 없는지? | E5: ="미완료 "&COUNTIF(시공!$D$5:$D$26,"×")&"건" -> 미완료 0건
B6: 계획서 | C6: 시운전 계획서를 감리단·감독관에 제출하고 승인받았는지?
C7: 시운전 일정이 토목·건축·전기 공정 완료 시점과 맞는지?
B8: 공급조건 | C8: 시운전 중 용수·전력·약품·운전인력 공급 주체가 확정됐는지?
C9: 유입수 확보(하수 유입 또는 청수) 계획이 있는지?
B10: 성능시험 조건 | C10: 보증수질 성능시험 조건(기간, 시료채취 지점·빈도, 판정방법)이 계약과 일치하는지?
A11: 설치 완료 확인 | B11: 포기장치 | C11: 터빈 설치 레벨이 HWL·LWL 기준 깊이에 맞는지?
C12: 십자구조물 높이와 위치가 도면대로 설치됐는지?
C13: 감속기 오일 규격·주입량과 누유 여부를 확인했는지?
B14: 배출장치 | C14: 디켄터 공기차단막이 부착됐는지?
C15: GUIDE RAIL·FLOAT ARM 수직도와 윈치 와이어 장력이 정상인지?
C16: 슬리브·배출관 BOP 레벨과 누수 여부를 확인했는지?
A17: 전기 계장 확인 | B17: 전원 | C17: 절연저항·접지저항 측정값이 기준 이내인지?
C18: 모터 상회전 방향과 터빈 회전방향이 일치하는지?
C19: 인버터 파라미터(상한 주파수, 가감속)가 설정값대로 입력됐는지?
B20: 계측·제어 | C20: 계측기(LS, LT, DO, MLSS) 교정과 지시값 검증이 됐는지?
C21: 제어반 인터록(저수위 정지, 과부하, 비상정지)이 작동하는지?
C22: 자동·수동 전환과 LOP 조작이 정상인지?
C23: 상위 통신과 경보 신호가 정상 전송되는지?
A24: 무부하 청수 시운전 | B24: 무부하 | C24: 무부하 단독운전 시 전류·진동·소음이 기준 이내인지?
C25: 정격 RPM과 실제 운전 RPM이 일치하는지?
B26: 청수 | C26: 청수 포기 운전에서 유동, 진동, 소음이 정상인지?
C27: 디켄터 상하강 행정·시간과 리미트스위치 정지 위치가 정확한지?
C28: 실측 배출시간이 설계 배출단계 시간 이내인지?
C29: 배출 후 잔류수위(LWL)가 설계값과 일치하는지?
C30: 공급펌프 기동·정지 수위와 사이클당 유입시간이 맞는지?
A31: 실부하 시운전 | B31: 초기운전 | C31: 식종 슬러지 반입량·성상이 계획대로 확보됐는지?
C32: 사이클 타임(유입/반응/침전/배출/휴지) 설정값이 설계와 일치하는지?
B33: 운전관리 | C33: MLSS·SV30·DO·pH 일일 관리 기록이 유지되는지?
C34: 침전단계 후 슬러지 계면이 배출고 아래로 유지되는지?
C35: SRT에 맞춰 잉여슬러지 인발이 이뤄지는지?
C36: 거품·슬러지 부상·사상균 발생 시 대응 조치를 기록했는지?
C37: 동절기 저수온 시 질산화 저하 대응 방안이 있는지?
B38: 연동운전 | C38: 총인처리설비·UV 소독설비와 연동 운전이 정상인지?
A39: 성능 시험 | B39: 시료·분석 | C39: 계획한 지점·빈도로 채취한 시료의 공인 분석기관 성적서로 보증수질 만족을 확인했는지?
B40: 판정 | C40: 계약 판정방법(평균·최대, 초과 허용 횟수) 기준으로 방류수 수질기준 대비 여유가 확보됐는지?
C41: 미달 항목의 원인분석과 보완 조치를 기록했는지?
...

Sheet 변경내역
A1: 시트 | B1: 구분 | C1: 변경 전 | D1: 변경 후 | E1: 사유
A2: 검토서 | B2: 오류 수정 | C2: 유입시간 판정 수식이 #REF! (기준 90분 칸 삭제됨) | D2: 1번 섹션에 '공급펌프 유입시간 기준(지침)' 입력칸 신설(D18=90분), 판정·조건부서식 재연결 | E2: 자동 판정이 작동하지 않던 버그
A3: 검토서 | B3: 삭제 | C3: 2번 섹션 '1차 처리수조 운전 수위 및 유효수심 검토' | D3: 삭제 (5번 섹션 '처리수조 유효용량 및 운전수위 검토'로 일원화) | E3: 중복. 현장에 별도 1차 처리수조가 있으면 6번 기타에 추가
A4: 검토서 | B4: 병합 | C4: '제어반 구성(인버터·PLC반/LOP 면수)' + '공법제어반 포함내용(PLC 이중화 등)' | D4: '제어반 구성 및 포함내용 검토 (인버터 · PLC 이중화 · LOP 면수)' | E4: 같은 제어반 구성 확인
A5: 검토서 | B5: 병합 | C5: '총인설비 공급 범위' + '총인 배관연결 scope' | D5: '총인설비 공급 범위 및 연결 scope 검토 (약품 · 배관 · 전기 · 제어)' | E5: 같은 scope 확인
A6: 검토서 | B6: 이관 | C6: 시공 시트 '포기장치·제어반 반입 및 양중 경로' | D6: 3번 섹션에 점검항목 추가 | E6: 설계도서 단계에서 검토할 항목
A7: 검토서 | B7: 이관 | C7: 시공 시트 '배출관 경로·레벨 (처리수조/총인설비까지)' | D7: 5번 섹션에 점검항목 추가 | E7: 설계도서 단계에서 검토할 항목
A8: 검토서 | B8: 문구 보강 | C8: 덮개 / 포기장치 간섭 / (+)구조물 / 계측기 항목 | D8: 시공 시트의 점검구 · 설치 위치 · 두께·레벨 · 브라켓 내용을 문구에 흡수 | E8: 시공 시트 설계도서 검토 섹션 삭제에 따른 흡수
A9: 시공 | B9: 축소 | C9: '설계도서 검토' 16개 항목 (검토서와 중복) | D9: '설계 재검토' 2개 항목 + 검토서 미해소 · 설계변경 건수 자동 표시 | E9: 상세 검토는 검토서에서 1회만
A10: 시공 | B10: 열 추가 | C10: 확인 열 없음 | D10: D열 '확인'(○, ×, N/A) 신설, 비고는 E열 | E10: 시운전 단계에서 시공 미완료 건수 집계용
A11: 시공 | B11: 병합 | C11: 제작승인도서 20개 항목 | D11: 12개 (제출시기·양식 / 시방서 차이·DEVIATION / 레벨·치수 4건 / 규격 2건 / 프로펠러·공기차단막 / 첨부서류 2건 병합) | E11: 같은 확인 행위의 반복
A12: 시공 | B12: 병합 | C12: 공장검사 첨부서류 2개, 준공 보고서·도면 2개 | D12: 각 1개 | E12: 동일 문구 반복
... A19: 검토서 | B19: 판정 기준 | C19: 배출소요시간 = Q/Cycle ÷ 배출유량 | D19: 배출 대상 유량(배출장치 설계유입량) 입력칸 신설, 배출소요시간을 QIN 기준으로 판정 (계산서와 같이 ROUND 3자리) | E19: 잉여슬러지 인발로 수위가 낮아져 실제 배출량은 Q/Cycle보다 작음 — QIN 기준이 맞음
